File: bridge-data/bridge_data.csv
Bridge_ID,Location,Age (years),Material,Length (m),Width (m),Height (m),Traffic_Volume (vehicles/day),Weather_Conditions,Water_Flow_Rate (m³/s),Maintenance_History,Stress (MPa),Strain (%),Tensile_Strength (MPa),Rainfall (mm),Material_Composition,Bridge_Design,Construction_Quality,Temperature (°C),Humidity (%),Collapse_Status
1,Region_1,26,Steel,50.0,5.0,10.0,100.0,Rainy,0.0,2010-01-01,0.0,0.0,200.0,0.0,"Steel 70%, Concrete 30%",Arch,Good,-30.0,0.0,Standing
2,Region_2,47,Concrete,50.19501950195019,5.004500450045004,10.009000900090008,100.99009900990099,Sunny,0.5000500050005,2010-01-02,0.010001000100010001,0.001000100010001,200.0800080008001,0.05000500050005,"Concrete 80%, Wood 20%",Beam,Good,-29.99199919991999,0.010001000100010001,Standing
60,Region_5,18,Wood,61.50615061506151,5.265526552655266,10.531053105310532,158.41584158415841,Windy,29.5029502950295,2010-03-01,0.5900590059005901,0.05900590059005901,204.7204720472047,2.95029502950295,"Concrete 80%, Wood 20%",Truss,Good,-29.52795279527953,0.5900590059005901,Standing
118,Region_3,24,Steel,72.81728172817282,5.526552655265527,11.053105310531054,215.84158415841586,Snowy,58.505850585058504,2010-04-28,1.17011701170117,0.11701170117011701,209.36093609360935,5.8505850585058505,"Steel 70%, Concrete 30%",Arch,Good,-29.063906390639065,1.17011701170117,Standing
176,Region_1,3,Concrete,84.12841284128413,5.787578757875788,11.575157515751576,273.26732673267327,Rainy,87.5087508750875,2010-06-25,1.7501750175017503,0.17501750175017503,214.001400140014,8.750875087508751,"Concrete 80%, Wood 20%",Beam,Good,-28.5998599859986,1.7501750175017503,Standing
234,Region_4,2,Wood,95.43954395439545,6.048604860486049,12.097209720972097,330.6930693069307,Cloudy,116.5116511651165,2010-08-22,2.3302330233023305,0.23302330233023302,218.64186418641864,11.65116511651165,"Concrete 80%, Wood 20%",Truss,Good,-28.135813581358136,2.3302330233023305,Standing
292,Region_2,14,Steel,106.75067506750675,6.30963096309631,12.61926192619262,388.1188118811881,Sunny,145.5145514551455,2010-10-19,2.9102910291029103,0.29102910291029105,223.2823282328233,14.55145514551455,"Steel 70%, Concrete 30%",Arch,Good,-27.671767176717672,2.9102910291029103,Standing
350,Region_5,20,Concrete,118.06180618061806,6.570657065706571,13.141314131413141,445.54455445544556,Windy,174.5174517451745,2010-12-16,3.4903490349034905,0.34903490349034905,227.92279227922793,17.451745174517452,"Concrete 80%, Wood 20%",Beam,Good,-27.20772077207721,3.4903490349034905,Standing
408,Region_3,47,Wood,129.37293729372936,6.8316831683168315,13.663366336633663,502.970297029703,Snowy,203.5203520352035,2011-02-12,4.070407040704071,0.40704070407040704,232.56325632563255,20.35203520352035,"Concrete 80%, Wood 20%",Truss,Good,-26.743674367436743,4.070407040704071,Standing
466,Region_1,34,Steel,140.68406840684068,7.092709270927093,14.185418541854187,560.3960396039604,Rainy,232.5232523252325,2011-04-11,4.65046504650465,0.46504650465046504,237.2037203720372,23.25232523252325,"Steel 70%, Concrete 30%",Arch,Good,-26.27962796279628,4.65046504650465,Standing
524,Region_4,36,Concrete,151.995199519952,7.353735373537354,14.707470747074709,617.8217821782179,Cloudy,261.5261526152615,2011-06-08,5.230523052305231,0.523052305230523,241.84418441844184,26.15261526152615,"Concrete 80%, Wood 20%",Beam,Good,-25.815581558155817,5.230523052305231,Standing
582,Region_2,36,Wood,163.3063306330633,7.614761476147615,15.22952295229523,675.2475247524752,Sunny,290.5290529052905,2011-08-05,5.810581058105811,0.581058105810581,246.4846484648465,29.05290529052905,"Concrete 80%, Wood 20%",Truss,Good,-25.35153515351535,5.810581058105811,Standing
640,Region_5,46,Steel,174.61746174617463,7.875787578757876,15.751575157515752,732.6732673267327,Windy,319.5319531953195,2011-10-02,6.390639063906391,0.639063906390639,251.12511251125113,31.95319531953195,"Steel 70%, Concrete 30%",Arch,Good,-24.887488748874887,6.390639063906391,Standing
698,Region_3,40,Concrete,185.9285928592859,8.136813681368137,16.273627362736274,790.09900990099,Snowy,348.5348534853485,2011-11-29,6.970697069706971,0.697069706970697,255.76557655765578,34.85348534853485,"Concrete 80%, Wood 20%",Beam,Good,-24.423442344234424,6.970697069706971,Standing
756,Region_1,47,Wood,197.23972397239723,8.397839783978398,16.795679567956796,847.5247524752475,Rainy,377.5377537753775,2012-01-26,7.550755075507551,0.755075507550755,260.4060406040604,37.75377537753775,"Concrete 80%, Wood 20%",Truss,Good,-23.95939593959396,7.550755075507551,Standing
814,Region_4,24,Steel,208.55085508550854,8.658865886588659,17.317731773177318,904.950495049505,Cloudy,406.5406540654065,2012-03-24,8.130813081308132,0.8130813081308131,265.04650465046507,40.65406540654065,"Steel 70%, Concrete 30%",Arch,Good,-23.495349534953494,8.130813081308132,Standing
872,Region_2,1,Concrete,219.86198619861986,8.91989198919892,17.83978397839784,962.3762376237623,Sunny,435.5435543554355,2012-05-21,8.71087108710871,0.8710871087108711,269.6869686968697,43.55435543554355,"Concrete 80%, Wood 20%",Beam,Good,-23.03130313031303,8.71087108710871,Standing
930,Region_5,14,Wood,231.17311731173118,9.18091809180918,18.36183618361836,1019.8019801980198,Windy,464.5464546454645,2012-07-18,9.290929092909291,0.9290929092909291,274.32743274327436,46.45464546454645,"Concrete 80%, Wood 20%",Truss,Good,-22.567256725672568,9.290929092909291,Standing
988,Region_3,41,Steel,242.4842484248425,9.441944194419442,18.883888388838884,1077.2277227722773,Snowy,493.5493549354935,2012-09-14,9.870987098709872,0.9870987098709871,278.967896789679,49.354935493549355,"Steel 70%, Concrete 30%",Arch,Good,-22.1032103210321,9.870987098709872,Standing
1046,Region_1,9,Concrete,253.7953795379538,9.702970297029703,19.405940594059405,1134.6534653465346,Rainy,522.5522552255225,2012-11-11,10.451045104510452,1.045104510451045,283.60836083608365,52.25522552255225,"Concrete 80%, Wood 20%",Beam,Good,-21.639163916391638,10.451045104510452,Standing
1104,Region_4,41,Wood,265.1065106510651,9.963996399639964,19.927992799279927,1192.079207920792,Cloudy,551.5551555155515,2013-01-08,11.031103110311031,1.1031103110311031,288.24882488248824,55.155515551555155,"Concrete 80%, Wood 20%",Truss,Good,-21.175117511751175,11.031103110311031,Standing
1162,Region_2,48,Steel,276.41764176417644,10.225022502250226,20.450045004500453,1249.5049504950496,Sunny,580.5580558055805,2013-03-07,11.611161116111612,1.161116111611161,292.8892889288929,58.05580558055805,"Steel 70%, Concrete 30%",Arch,Good,-20.711071107110712,11.611161116111612,Standing
1220,Region_5,33,Concrete,287.7287728772877,10.486048604860486,20.97209720972097,1306.930693069307,Windy,609.5609560956095,2013-05-04,12.191219121912193,1.2191219121912191,297.5297529752975,60.956095609560954,"Concrete 80%, Wood 20%",Beam,Good,-20.24702470247025,12.191219121912193,Standing
1278,Region_3,29,Wood,299.039903990399,10.747074707470748,21.494149414941496,1364.3564356435643,Snowy,638.5638563856385,2013-07-01,12.771277127712771,1.2771277127712772,302.1702170217022,63.85638563856385,"Concrete 80%, Wood 20%",Truss,Good,-19.782978297829782,12.771277127712771,Standing
1336,Region_1,37,Steel,310.35103510351036,11.008100810081007,22.016201620162015,1421.7821782178219,Rainy,667.5667566756675,2013-08-28,13.351335133513352,1.3351335133513351,306.8106810681068,66.75667566756675,"Steel 70%, Concrete 30%",Arch,Good,-19.31893189318932,13.351335133513352,Standing
1394,Region_4,19,Concrete,321.66216621662164,11.26912691269127,22.53825382538254,1479.2079207920792,Cloudy,696.5696569656965,2013-10-25,13.931393139313933,1.3931393139313932,311.45114511451146,69.65696569656966,"Concrete 80%, Wood 20%",Beam,Good,-18.854885488548852,13.931393139313933,Standing
1452,Region_2,7,Wood,332.973297329733,11.53015301530153,23.06030603060306,1536.6336633663366,Sunny,725.5725572557255,2013-12-22,14.511451145114512,1.4511451145114511,316.0916091609161,72.55725572557256,"Concrete 80%, Wood 20%",Truss,Good,-18.39083908390839,14.511451145114512,Standing
1510,Region_5,41,Steel,344.2844284428443,11.791179117911792,23.582358235823584,1594.059405940594,Windy,754.5754575457545,2014-02-18,15.091509150915092,1.5091509150915092,320.73207320732075,75.45754575457545,"Steel 70%, Concrete 30%",Arch,Good,-17.926792679267926,15.091509150915092,Standing
1568,Region_3,2,Concrete,355.5955595559556,12.052205220522051,24.104410441044102,1651.4851485148515,Snowy,783.5783578357835,2014-04-17,15.671567156715673,1.5671567156715671,325.3725372537254,78.35783578357835,"Concrete 80%, Wood 20%",Beam,Good,-17.462746274627463,15.671567156715673,Standing
1626,Region_1,12,Wood,366.9066906690669,12.313231323132314,24.626462646264628,1708.9108910891089,Rainy,812.5812581258125,2014-06-14,16.251625162516252,1.6251625162516252,330.01300130013,81.25812581258126,"Concrete 80%, Wood 20%",Truss,Good,-16.998699869987,16.251625162516252,Standing
1684,Region_4,15,Steel,378.2178217821782,12.574257425742575,25.14851485148515,1766.3366336633662,Cloudy,841.5841584158416,2014-08-11,16.831683168316832,1.683168316831683,334.65346534653463,84.15841584158416,"Steel 70%, Concrete 30%",Arch,Good,-16.534653465346537,16.831683168316832,Standing
1742,Region_2,12,Concrete,389.52895289528954,12.835283528352836,25.67056705670567,1823.7623762376238,Sunny,870.5870587058705,2014-10-08,17.411741174117413,1.7411741174117412,339.2939293929393,87.05870587058705,"Concrete 80%, Wood 20%",Beam,Good,-16.07060706070607,17.411741174117413,Standing
1800,Region_5,8,Wood,400.8400840084008,13.096309630963097,26.192619261926193,1881.1881188118812,Windy,899.5899589958996,2014-12-05,17.991799179917994,1.799179917991799,343.9343934393439,89.95899589958995,"Concrete 80%, Wood 20%",Truss,Good,-15.606560656065607,17.991799179917994,Standing
1858,Region_3,35,Steel,412.15121512151217,13.357335733573358,26.714671467146715,1938.6138613861385,Snowy,928.5928592859285,2015-02-01,18.571857185718574,1.8571857185718572,348.57485748574857,92.85928592859285,"Steel 70%, Concrete 30%",Arch,Good,-15.142514251425142,18.571857185718574,Standing
1916,Region_1,45,Concrete,423.46234623462345,13.618361836183619,27.236723672367237,1996.039603960396,Rainy,957.5957595759576,2015-03-31,19.15191519151915,1.915191519151915,353.2153215321532,95.75957595759576,"Concrete 80%, Wood 20%",Beam,Good,-14.67846784678468,19.15191519151915,Standing
1974,Region_4,13,Wood,434.7734773477348,13.87938793879388,27.75877587758776,2053.4653465346537,Cloudy,986.5986598659865,2015-05-28,19.731973197319732,1.9731973197319732,357.85578557855786,98.65986598659866,"Concrete 80%, Wood 20%",Truss,Good,-14.214421442144214,19.731973197319732,Standing
2032,Region_2,5,Steel,446.0846084608461,14.14041404140414,28.28082808280828,2110.891089108911,Sunny,1015.6015601560155,2015-07-25,20.312031203120313,2.031203120312031,362.4962496249625,101.56015601560155,"Steel 70%, Concrete 30%",Arch,Good,-13.750375037503751,20.312031203120313,Standing
2090,Region_5,7,Concrete,457.39573957395737,14.401440144014401,28.802880288028803,2168.3168316831684,Windy,1044.6044604460444,2015-09-21,20.892089208920893,2.0892089208920894,367.13671367136715,104.46044604460445,"Concrete 80%, Wood 20%",Beam,Good,-13.286328632863285,20.892089208920893,Standing
2148,Region_3,46,Wood,468.7068706870687,14.662466246624662,29.324932493249324,2225.7425742574255,Snowy,1073.6073607360736,2015-11-18,21.472147214721474,2.1472147214721473,371.7771777177718,107.36073607360736,"Concrete 80%, Wood 20%",Truss,Good,-12.822282228222821,21.472147214721474,Standing
2206,Region_1,14,Steel,480.01800180018,14.923492349234923,29.846984698469846,2283.168316831683,Rainy,1102.6102610261025,2016-01-15,22.052205220522055,2.205220522052205,376.41764176417644,110.26102610261026,"Steel 70%, Concrete 30%",Arch,Good,-12.358235823582358,22.052205220522055,Standing
2264,Region_4,1,Concrete,491.32913291329135,15.184518451845184,30.36903690369037,2340.5940594059407,Cloudy,1131.6131613161315,2016-03-13,22.63226322632263,2.263226322632263,381.0581058105811,113.16131613161315,"Concrete 80%, Wood 20%",Beam,Good,-11.894189418941895,22.63226322632263,Standing
2322,Region_2,47,Wood,502.64026402640263,15.445544554455445,30.89108910891089,2398.019801980198,Sunny,1160.6160616061604,2016-05-10,23.212321232123212,2.3212321232123214,385.6985698569857,116.06160616061605,"Concrete 80%, Wood 20%",Truss,Good,-11.430143014301429,23.212321232123212,Standing
2380,Region_5,13,Steel,513.9513951395139,15.706570657065708,31.413141314131416,2455.4455445544554,Windy,1189.6189618961896,2016-07-07,23.792379237923793,2.3792379237923793,390.3390339033904,118.96189618961895,"Steel 70%, Concrete 30%",Arch,Good,-10.966096609660966,23.792379237923793,Standing
2438,Region_3,15,Concrete,525.2625262526253,15.967596759675969,31.935193519351937,2512.871287128713,Snowy,1218.6218621862186,2016-09-03,24.372437243724374,2.437243724372437,394.979497949795,121.86218621862186,"Concrete 80%, Wood 20%",Beam,Good,-10.502050205020502,24.372437243724374,Standing
2496,Region_1,16,Wood,536.5736573657366,16.22862286228623,32.45724572457246,2570.29702970297,Rainy,1247.6247624762475,2016-10-31,24.952495249524954,2.495249524952495,399.61996199619966,124.76247624762476,"Concrete 80%, Wood 20%",Truss,Good,-10.03800380038004,24.952495249524954,Standing
2554,Region_4,0,Steel,547.8847884788479,16.48964896489649,32.97929792979298,2627.7227722772277,Cloudy,1276.6276627662764,2016-12-28,25.532553255325535,2.5532553255325534,404.2604260426043,127.66276627662765,"Steel 70%, Concrete 30%",Arch,Good,-9.573957395739573,25.532553255325535,Standing
2612,Region_2,28,Concrete,559.1959195919592,16.75067506750675,33.5013501350135,2685.1485148514853,Sunny,1305.6305630563056,2017-02-24,26.112611261126116,2.6112611261126113,408.90089008900895,130.56305630563057,"Concrete 80%, Wood 20%",Beam,Good,-9.10991099109911,26.112611261126116,Standing
2670,Region_5,45,Wood,570.5070507050705,17.011701170117014,34.02340234023403,2742.5742574257424,Windy,1334.6334633463346,2017-04-23,26.692669266926693,2.669266926692669,413.54135413541354,133.46334633463346,"Concrete 80%, Wood 20%",Truss,Good,-8.645864586458647,26.692669266926693,Standing
2728,Region_3,34,Steel,581.8181818181819,17.272727272727273,34.54545454545455,2800.0,Snowy,1363.6363636363635,2017-06-20,27.272727272727273,2.727272727272727,418.1818181818182,136.36363636363635,"Steel 70%, Concrete 30%",Arch,Good,-8.181818181818183,27.272727272727273,Standing
2786,Region_1,45,Concrete,593.1293129312932,17.533753375337533,35.067506750675065,2857.4257425742576,Rainy,1392.6392639263925,2017-08-17,27.852785278527854,2.7852785278527854,422.82228222822283,139.26392639263926,"Concrete 80%, Wood 20%",Beam,Good,-7.717771777177717,27.852785278527854,Standing
2844,Region_4,27,Wood,604.4404440444044,17.794779477947795,35.58955895589559,2914.8514851485147,Cloudy,1421.6421642164216,2017-10-14,28.432843284328435,2.8432843284328433,427.4627462746275,142.16421642164215,"Concrete 80%, Wood 20%",Truss,Good,-7.253725372537254,28.432843284328435,Standing
2902,Region_2,26,Steel,615.7515751575157,18.055805580558058,36.111611161116116,2972.2772277227723,Sunny,1450.6450645064506,2017-12-11,29.012901290129015,2.901290129012901,432.1032103210321,145.06450645064507,"Steel 70%, Concrete 30%",Arch,Good,-6.789678967896791,29.012901290129015,Standing
2960,Region_5,44,Concrete,627.062706270627,18.316831683168317,36.633663366336634,3029.70297029703,Windy,1479.6479647964795,2018-02-07,29.592959295929596,2.9592959295929595,436.74367436743677,147.96479647964796,"Concrete 80%, Wood 20%",Beam,Good,-6.325632563256324,29.592959295929596,Standing
3018,Region_3,48,Wood,638.3738373837384,18.577857785778576,37.15571557155715,3087.128712871287,Snowy,1508.6508650865085,2018-04-06,30.173017301730173,3.0173017301730174,441.38413841384136,150.86508650865085,"Concrete 80%, Wood 20%",Truss,Good,-5.861586158615861,30.173017301730173,Standing
3076,Region_1,37,Steel,649.6849684968497,18.83888388838884,37.67776777677768,3144.5544554455446,Rainy,1537.6537653765374,2018-06-03,30.753075307530754,3.0753075307530753,446.024602460246,153.76537653765376,"Steel 70%, Concrete 30%",Arch,Good,-5.397539753975398,30.753075307530754,Standing
3134,Region_4,14,Concrete,660.996099609961,19.0999099909991,38.1998199819982,3201.980198019802,Cloudy,1566.6566656665666,2018-07-31,31.333133313331334,3.133313331333133,450.66506650665065,156.66566656665665,"Concrete 80%, Wood 20%",Beam,Good,-4.933493349334935,31.333133313331334,Standing
3192,Region_2,22,Wood,672.3072307230723,19.36093609360936,38.72187218721872,3259.4059405940593,Sunny,1595.6595659565955,2018-09-27,31.913191319131915,3.1913191319131915,455.3055305530553,159.56595659565957,"Concrete 80%, Wood 20%",Truss,Good,-4.469446944694468,31.913191319131915,Standing
3250,Region_5,33,Steel,683.6183618361836,19.62196219621962,39.24392439243924,3316.831683168317,Windy,1624.6624662466245,2018-11-24,32.49324932493249,3.2493249324932494,459.94599459945994,162.46624662466246,"Steel 70%, Concrete 30%",Arch,Good,-4.005400540054005,32.49324932493249,Standing
3308,Region_3,12,Concrete,694.929492949295,19.882988298829883,39.765976597659765,3374.257425742574,Snowy,1653.6653665366534,2019-01-21,33.07330733073307,3.3073307330733073,464.5864586458646,165.36653665366535,"Concrete 80%, Wood 20%",Beam,Good,-3.541354135413542,33.07330733073307,Standing
3366,Region_1,15,Wood,706.2406240624063,20.144014401440145,40.28802880288029,3431.6831683168316,Rainy,1682.6682668266826,2019-03-20,33.65336533653365,3.365336533653365,469.2269226922692,168.26682668266827,"Concrete 80%, Wood 20%",Truss,Good,-3.0773077307730787,33.65336533653365,Standing
3424,Region_4,12,Steel,717.5517551755175,20.405040504050405,40.81008100810081,3489.108910891089,Cloudy,1711.6711671167116,2019-05-17,34.233423342334234,3.4233423342334235,473.8673867386739,171.16711671167116,"Steel 70%, Concrete 30%",Arch,Good,-2.613261326132612,34.233423342334234,Standing
3482,Region_2,42,Concrete,728.8628862886288,20.666066606660667,41.332133213321335,3546.5346534653463,Sunny,1740.6740674067405,2019-07-14,34.813481348134815,3.4813481348134814,478.5078507850785,174.06740674067404,"Concrete 80%, Wood 20%",Beam,Good,-2.149214921492149,34.813481348134815,Standing
3540,Region_5,16,Wood,740.1740174017401,20.92709270927093,41.85418541854186,3603.960396039604,Windy,1769.6769676967695,2019-09-10,35.393539353935395,3.5393539353935393,483.14831483148316,176.96769676967696,"Concrete 80%, Wood 20%",Truss,Good,-1.685168516851686,35.393539353935395,Standing
3598,Region_3,33,Steel,751.4851485148515,21.18811881188119,42.37623762376238,3661.3861386138615,Snowy,1798.6798679867986,2019-11-07,35.973597359735976,3.5973597359735976,487.7887788778878,179.86798679867985,"Steel 70%, Concrete 30%",Arch,Good,-1.2211221122112192,35.973597359735976,Standing
3656,Region_1,43,Concrete,762.7962796279628,21.44914491449145,42.8982898289829,3718.8118811881186,Rainy,1827.6827682768276,2020-01-04,36.55365536553656,3.6553655365536555,492.42924292429245,182.76827682768277,"Concrete 80%, Wood 20%",Beam,Good,-0.7570757075707562,36.55365536553656,Standing
3714,Region_4,40,Wood,774.1074107410741,21.71017101710171,43.42034203420342,3776.237623762376,Cloudy,1856.6856685668565,2020-03-02,37.13371337133714,3.7133713371337134,497.0697069706971,185.66856685668566,"Concrete 80%, Wood 20%",Truss,Good,-0.29302930293029306,37.13371337133714,Standing
3772,Region_2,0,Steel,785.4185418541854,21.97119711971197,43.94239423942394,3833.6633663366338,Sunny,1885.6885688568855,2020-04-29,37.71377137713772,3.7713771377137713,501.71017101710174,188.56885688568855,"Steel 70%, Concrete 30%",Arch,Good,0.17101710171017004,37.71377137713772,Standing
3830,Region_5,37,Concrete,796.7296729672968,22.232223222322233,44.464446444644466,3891.089108910891,Windy,1914.6914691469146,2020-06-26,38.2938293829383,3.8293829382938296,506.3506350635064,191.46914691469146,"Concrete 80%, Wood 20%",Beam,Good,0.6350635063506367,38.2938293829383,Standing
3888,Region_3,6,Wood,808.0408040804081,22.493249324932492,44.986498649864984,3948.5148514851485,Snowy,1943.6943694369436,2020-08-23,38.87388738873888,3.8873887388738875,510.99109910991103,194.36943694369435,"Concrete 80%, Wood 20%",Truss,Good,1.0991099109910998,38.87388738873888,Standing
3946,Region_1,31,Steel,819.3519351935194,22.754275427542755,45.50855085508551,4005.940594059406,Rainy,1972.6972697269725,2020-10-20,39.45394539453945,3.9453945394539454,515.6315631563157,197.26972697269727,"Steel 70%, Concrete 30%",Arch,Good,1.5631563156315629,39.45394539453945,Standing
4004,Region_4,25,Concrete,830.6630663066306,23.015301530153017,46.030603060306035,4063.366336633663,Cloudy,2001.7001700170015,2020-12-17,40.03400340034003,4.003400340034004,520.2720272027202,200.17001700170016,"Concrete 80%, Wood 20%",Beam,Good,2.0272027202720295,40.03400340034003,Standing
4062,Region_2,13,Wood,841.9741974197419,23.276327632763277,46.55265526552655,4120.79207920792,Sunny,2030.7030703070304,2021-02-13,40.614061406140614,4.061406140614062,524.912491249125,203.07030703070305,"Concrete 80%, Wood 20%",Truss,Good,2.4912491249124926,40.614061406140614,Standing
4120,Region_5,49,Steel,853.2853285328533,23.53735373537354,47.07470747074708,4178.217821782178,Windy,2059.7059705970596,2021-04-12,41.194119411941195,4.1194119411941195,529.5529552955295,205.97059705970597,"Steel 70%, Concrete 30%",Arch,Good,2.9552955295529557,41.194119411941195,Standing
4178,Region_3,43,Concrete,864.5964596459646,23.7983798379838,47.5967596759676,4235.6435643564355,Snowy,2088.7088708870883,2021-06-09,41.774177417741775,4.177417741774177,534.1934193419343,208.87088708870886,"Concrete 80%, Wood 20%",Beam,Good,3.419341934193419,41.774177417741775,Standing
4236,Region_1,20,Wood,875.9075907590759,24.05940594059406,48.11881188118812,4293.069306930693,Rainy,2117.7117711771175,2021-08-06,42.354235423542356,4.235423542354235,538.8338833883388,211.77117711771177,"Concrete 80%, Wood 20%",Truss,Good,3.883388338833882,42.354235423542356,Standing
4294,Region_4,37,Steel,887.2187218721872,24.32043204320432,48.64086408640864,4350.495049504951,Cloudy,2146.7146714671467,2021-10-03,42.93429342934294,4.293429342934293,543.4743474347435,214.67146714671466,"Steel 70%, Concrete 30%",Arch,Good,4.347434743474345,42.93429342934294,Standing
4352,Region_2,35,Concrete,898.5298529852985,24.581458145814583,49.162916291629166,4407.920792079208,Sunny,2175.7175717571754,2021-11-30,43.51435143514352,4.351435143514352,548.1148114811481,217.57175717571755,"Concrete 80%, Wood 20%",Beam,Good,4.811481148114815,43.51435143514352,Standing
4410,Region_5,29,Wood,909.8409840984099,24.842484248424842,49.684968496849685,4465.346534653465,Windy,2204.7204720472046,2022-01-27,44.0944094409441,4.40944094409441,552.7552755275528,220.47204720472047,"Concrete 80%, Wood 20%",Truss,Good,5.275527552755278,44.0944094409441,Standing
4468,Region_3,19,Steel,921.1521152115212,25.103510351035105,50.20702070207021,4522.772277227723,Snowy,2233.7233723372337,2022-03-26,44.67446744674468,4.467446744674468,557.3957395739574,223.37233723372336,"Steel 70%, Concrete 30%",Arch,Good,5.739573957395741,44.67446744674468,Standing
4526,Region_1,19,Concrete,932.4632463246325,25.364536453645364,50.72907290729073,4580.19801980198,Rainy,2262.7262726272625,2022-05-23,45.25452545254526,4.525452545254526,562.0362036203621,226.27262726272625,"Concrete 80%, Wood 20%",Beam,Good,6.2036203620362045,45.25452545254526,Standing
4584,Region_4,11,Wood,943.7743774377437,25.625562556255627,51.251125112511254,4637.623762376237,Cloudy,2291.7291729172916,2022-07-20,45.83458345834584,4.5834583458345834,566.6766676667667,229.17291729172916,"Concrete 80%, Wood 20%",Truss,Good,6.667666766676668,45.83458345834584,Standing
4642,Region_2,33,Steel,955.085508550855,25.886588658865886,51.77317731773177,4695.049504950495,Sunny,2320.7320732073204,2022-09-16,46.41464146414642,4.641464146414641,571.3171317131714,232.07320732073205,"Steel 70%, Concrete 30%",Arch,Good,7.131713171317131,46.41464146414642,Standing
4700,Region_5,2,Concrete,966.3966396639664,26.14761476147615,52.2952295229523,4752.475247524752,Windy,2349.7349734973495,2022-11-13,46.994699469946994,4.699469946994699,575.957595759576,234.97349734973497,"Concrete 80%, Wood 20%",Beam,Good,7.595759575957594,46.994699469946994,Standing
4758,Region_3,17,Wood,977.7077707770777,26.408640864086408,52.817281728172816,4809.9009900990095,Snowy,2378.7378737873787,2023-01-10,47.574757475747575,4.757475747574757,580.5980598059806,237.87378737873786,"Concrete 80%, Wood 20%",Truss,Good,8.059805980598057,47.574757475747575,Standing
4816,Region_1,3,Steel,989.018901890189,26.66966696669667,53.33933393339334,4867.3267326732675,Rainy,2407.7407740774074,2023-03-09,48.154815481548155,4.815481548154816,585.2385238523852,240.77407740774075,"Steel 70%, Concrete 30%",Arch,Good,8.523852385238527,48.154815481548155,Standing
4874,Region_4,15,Concrete,1000.3300330033003,26.93069306930693,53.86138613861386,4924.752475247525,Cloudy,2436.7436743674366,2023-05-06,48.734873487348736,4.873487348734874,589.8789878987899,243.67436743674367,"Concrete 80%, Wood 20%",Beam,Good,8.98789878987899,48.734873487348736,Standing
4932,Region_2,39,Wood,1011.6411641164117,27.191719171917192,54.383438343834385,4982.178217821782,Sunny,2465.7465746574653,2023-07-03,49.31493149314932,4.931493149314932,594.5194519451945,246.57465746574655,"Concrete 80%, Wood 20%",Truss,Good,9.451945194519453,49.31493149314932,Standing
4990,Region_5,26,Steel,1022.952295229523,27.452745274527455,54.90549054905491,5039.60396039604,Windy,2494.7494749474945,2023-08-30,49.8949894989499,4.9894989498949895,599.1599159915992,249.47494749474947,"Steel 70%, Concrete 30%",Arch,Good,9.915991599159916,49.8949894989499,Standing
5048,Region_3,20,Concrete,1034.2634263426344,27.713771377137714,55.42754275427543,5097.029702970297,Snowy,2523.7523752375237,2023-10-27,50.47504750475048,5.047504750475047,603.8003800380038,252.37523752375236,"Concrete 80%, Wood 20%",Beam,Good,10.38003800380038,50.47504750475048,Standing
5106,Region_1,38,Wood,1045.5745574557454,27.974797479747977,55.949594959495954,5154.455445544554,Rainy,2552.7552755275524,2023-12-24,51.05510551055106,5.105510551055105,608.4408440844085,255.27552755275525,"Concrete 80%, Wood 20%",Truss,Good,10.844084408440843,51.05510551055106,Standing
5164,Region_4,41,Steel,1056.885688568857,28.235823582358236,56.47164716471647,5211.881188118812,Cloudy,2581.7581758175816,2024-02-20,51.63516351635164,5.163516351635163,613.0813081308131,258.17581758175817,"Steel 70%, Concrete 30%",Arch,Good,11.308130813081306,51.63516351635164,Standing
5222,Region_2,7,Concrete,1068.1968196819682,28.4968496849685,56.993699369937,5269.306930693069,Sunny,2610.7610761076107,2024-04-18,52.21522152215222,5.221522152215222,617.7217721772178,261.0761076107611,"Concrete 80%, Wood 20%",Beam,Good,11.772177217721776,52.21522152215222,Standing
5280,Region_5,32,Wood,1079.5079507950795,28.757875787578758,57.515751575157516,5326.732673267326,Windy,2639.7639763976395,2024-06-15,52.7952795279528,5.27952795279528,622.3622362236224,263.97639763976395,"Concrete 80%, Wood 20%",Truss,Good,12.236223622362239,52.7952795279528,Standing
5338,Region_3,34,Steel,1090.8190819081908,29.01890189018902,58.03780378037804,5384.158415841584,Snowy,2668.7668766876686,2024-08-12,53.37533753375338,5.337533753375338,627.002700270027,266.87668766876686,"Steel 70%, Concrete 30%",Arch,Good,12.700270027002702,53.37533753375338,Standing
5396,Region_1,32,Concrete,1102.130213021302,29.27992799279928,58.55985598559856,5441.584158415842,Rainy,2697.7697769776973,2024-10-09,53.955395539553955,5.395539553955396,631.6431643164317,269.7769776977698,"Concrete 80%, Wood 20%",Beam,Good,13.164316431643165,53.955395539553955,Standing
5454,Region_4,43,Wood,1113.4413441344134,29.540954095409543,59.081908190819085,5499.009900990099,Cloudy,2726.7726772677265,2024-12-06,54.535453545354535,5.4535453545354535,636.2836283628362,272.67726772677264,"Concrete 80%, Wood 20%",Truss,Good,13.628362836283628,54.535453545354535,Standing
5512,Region_2,26,Steel,1124.7524752475247,29.801980198019802,59.603960396039604,5556.435643564357,Sunny,2755.7755775577557,2025-02-02,55.115511551155116,5.511551155115511,640.924092409241,275.57755775577556,"Steel 70%, Concrete 30%",Arch,Good,14.092409240924091,55.115511551155116,Standing
5570,Region_5,35,Concrete,1136.063606360636,30.063006300630065,60.12601260126013,5613.861386138614,Windy,2784.7784778477844,2025-04-01,55.6955695569557,5.569556955695569,645.5645564556455,278.4778477847785,"Concrete 80%, Wood 20%",Beam,Good,14.556455645564554,55.6955695569557,Standing
5628,Region_3,22,Wood,1147.3747374737475,30.324032403240324,60.64806480648065,5671.287128712871,Snowy,2813.7813781378136,2025-05-29,56.27562756275628,5.627562756275627,650.2050205020503,281.37813781378134,"Concrete 80%, Wood 20%",Truss,Good,15.020502050205017,56.27562756275628,Standing
5686,Region_1,14,Steel,1158.6858685868588,30.585058505850586,61.17011701170117,5728.712871287129,Rainy,2842.7842784278428,2025-07-26,56.85568556855686,5.685568556855686,654.8454845484548,284.27842784278425,"Steel 70%, Concrete 30%",Arch,Good,15.484548454845488,56.85568556855686,Standing
5744,Region_4,9,Concrete,1169.99699969997,30.846084608460846,61.69216921692169,5786.138613861386,Cloudy,2871.7871787178715,2025-09-22,57.43574357435744,5.743574357435744,659.4859485948596,287.17871787178717,"Concrete 80%, Wood 20%",Beam,Good,15.94859485948595,57.43574357435744,Standing
5802,Region_2,8,Wood,1181.3081308130813,31.10711071107111,62.21422142214222,5843.564356435643,Sunny,2900.7900790079007,2025-11-19,58.01580158015802,5.801580158015802,664.1264126412641,290.0790079007901,"Concrete 80%, Wood 20%",Truss,Good,16.412641264126414,58.01580158015802,Standing
5860,Region_5,47,Steel,1192.6192619261926,31.368136813681367,62.736273627362735,5900.990099009901,Windy,2929.7929792979294,2026-01-16,58.5958595859586,5.85958595859586,668.7668766876689,292.97929792979295,"Steel 70%, Concrete 30%",Arch,Good,16.876687668766877,58.5958595859586,Standing
5918,Region_3,1,Concrete,1203.930393039304,31.62916291629163,63.25832583258326,5958.415841584158,Snowy,2958.7958795879586,2026-03-15,59.17591759175918,5.9175917591759175,673.4073407340734,295.87958795879587,"Concrete 80%, Wood 20%",Beam,Good,17.34073407340734,59.17591759175918,Standing
5976,Region_1,43,Wood,1215.2415241524152,31.89018901890189,63.78037803780378,6015.841584158416,Rainy,2987.7987798779877,2026-05-12,59.75597559755976,5.975597559755975,678.0478047804781,298.7798779877988,"Concrete 80%, Wood 20%",Truss,Good,17.804780478047803,59.75597559755976,Standing
6034,Region_4,7,Steel,1226.5526552655265,32.15121512151215,64.3024302430243,6073.267326732674,Cloudy,3016.8016801680164,2026-07-09,60.33603360336034,6.033603360336033,682.6882688268827,301.68016801680164,"Steel 70%, Concrete 30%",Arch,Good,18.268826882688266,60.33603360336034,Standing
6092,Region_2,24,Concrete,1237.8637863786378,32.41224122412241,64.82448244824482,6130.693069306931,Sunny,3045.8045804580456,2026-09-05,60.91609160916092,6.091609160916092,687.3287328732874,304.58045804580456,"Concrete 80%, Wood 20%",Beam,Good,18.732873287328736,60.91609160916092,Standing
6150,Region_5,1,Wood,1249.174917491749,32.67326732673267,65.34653465346534,6188.118811881188,Windy,3074.8074807480743,2026-11-02,61.496149614961496,6.14961496149615,691.969196919692,307.4807480748075,"Concrete 80%, Wood 20%",Truss,Good,19.1969196919692,61.496149614961496,Standing
6208,Region_3,18,Steel,1260.4860486048606,32.93429342934294,65.86858685868587,6245.544554455446,Snowy,3103.8103810381035,2026-12-30,62.07620762076208,6.207620762076208,696.6096609660966,310.38103810381034,"Steel 70%, Concrete 30%",Arch,Good,19.660966096609663,62.07620762076208,Standing
6266,Region_1,33,Concrete,1271.7971797179719,33.195319531953196,66.39063906390639,6302.970297029703,Rainy,3132.8132813281327,2027-02-26,62.65626562656266,6.265626562656266,701.2501250125013,313.28132813281326,"Concrete 80%, Wood 20%",Beam,Good,20.125012501250126,62.65626562656266,Standing
6324,Region_4,2,Wood,1283.1083108310831,33.45634563456346,66.91269126912692,6360.39603960396,Cloudy,3161.8161816181614,2027-04-25,63.23632363236324,6.323632363236324,705.8905890589059,316.1816181618162,"Concrete 80%, Wood 20%",Truss,Good,20.58905890589059,63.23632363236324,Standing
6382,Region_2,3,Steel,1294.4194419441944,33.71737173717372,67.43474347434744,6417.821782178218,Sunny,3190.8190819081906,2027-06-22,63.81638163816382,6.3816381638163815,710.5310531053105,319.0819081908191,"Steel 70%, Concrete 30%",Arch,Good,21.053105310531052,63.81638163816382,Standing
6440,Region_5,24,Concrete,1305.7305730573057,33.97839783978398,67.95679567956796,6475.247524752475,Windy,3219.8219821982198,2027-08-19,64.3964396439644,6.439643964396439,715.1715171517152,321.98219821982195,"Concrete 80%, Wood 20%",Beam,Good,21.517151715171515,64.3964396439644,Standing
6498,Region_3,49,Wood,1317.041704170417,34.23942394239424,68.47884788478848,6532.6732673267325,Snowy,3248.8248824882485,2027-10-16,64.97649764976498,6.497649764976497,719.8119811981198,324.88248824882487,"Concrete 80%, Wood 20%",Truss,Good,21.981198119811978,64.97649764976498,Standing
6556,Region_1,41,Steel,1328.3528352835283,34.5004500450045,69.000900090009,6590.0990099009905,Rainy,3277.8277827782777,2027-12-13,65.55655565556556,6.555655565556556,724.4524452445245,327.7827782778278,"Steel 70%, Concrete 30%",Arch,Good,22.44524452445245,65.55655565556556,Standing
6614,Region_4,44,Concrete,1339.6639663966396,34.76147614761476,69.52295229522952,6647.524752475248,Cloudy,3306.8306830683064,2028-02-09,66.13661366136614,6.613661366136614,729.0929092909291,330.68306830683065,"Concrete 80%, Wood 20%",Beam,Good,22.90929092909291,66.13661366136614,Standing
6672,Region_2,39,Wood,1350.9750975097509,35.022502250225024,70.04500450045005,6704.950495049505,Sunny,3335.8335833583355,2028-04-07,66.71667166716672,6.671667166716672,733.7333733373338,333.58335833583357,"Concrete 80%, Wood 20%",Truss,Good,23.373337333733375,66.71667166716672,Standing
6730,Region_5,42,Steel,1362.2862286228624,35.28352835283528,70.56705670567057,6762.376237623762,Windy,3364.8364836483647,2028-06-04,67.2967296729673,6.72967296729673,738.3738373837384,336.4836483648365,"Steel 70%, Concrete 30%",Arch,Good,23.837383738373838,67.2967296729673,Standing
6788,Region_3,35,Concrete,1373.5973597359737,35.54455445544555,71.0891089108911,6819.80198019802,Snowy,3393.8393839383934,2028-08-01,67.87678767876788,6.787678767876788,743.0143014301431,339.38393839383934,"Concrete 80%, Wood 20%",Beam,Good,24.3014301430143,67.87678767876788,Standing
6846,Region_1,44,Wood,1384.908490849085,35.80558055805581,71.61116111611162,6877.227722772277,Rainy,3422.8422842284226,2028-09-28,68.45684568456846,6.8456845684568455,747.6547654765477,342.28422842284226,"Concrete 80%, Wood 20%",Truss,Good,24.765476547654764,68.45684568456846,Standing
6904,Region_4,24,Steel,1396.2196219621962,36.06660666066607,72.13321332133214,6934.653465346534,Cloudy,3451.8451845184513,2028-11-25,69.03690369036904,6.903690369036903,752.2952295229524,345.1845184518452,"Steel 70%, Concrete 30%",Arch,Good,25.229522952295227,69.03690369036904,Standing
6962,Region_2,5,Concrete,1407.5307530753075,36.32763276327633,72.65526552655265,6992.079207920792,Sunny,3480.8480848084805,2029-01-22,69.61696169616962,6.961696169616962,756.935693569357,348.08480848084804,"Concrete 80%, Wood 20%",Beam,Good,25.693569356935697,69.61696169616962,Standing
7020,Region_5,18,Wood,1418.8418841884188,36.588658865886586,73.17731773177317,7049.504950495049,Windy,3509.8509850985097,2029-03-21,70.1970197019702,7.01970197019702,761.5761576157616,350.98509850985096,"Concrete 80%, Wood 20%",Truss,Good,26.15761576157616,70.1970197019702,Standing
7078,Region_3,28,Steel,1430.15301530153,36.84968496849685,73.6993699369937,7106.9306930693065,Snowy,3538.8538853885384,2029-05-18,70.77707770777079,7.077707770777078,766.2166216621663,353.8853885388539,"Steel 70%, Concrete 30%",Arch,Good,26.621662166216623,70.77707770777079,Standing
7136,Region_1,37,Concrete,1441.4641464146414,37.11071107110711,74.22142214221422,7164.3564356435645,Rainy,3567.8567856785676,2029-07-15,71.35713571357137,7.135713571357136,770.8570857085709,356.7856785678568,"Concrete 80%, Wood 20%",Beam,Good,27.085708570857086,71.35713571357137,Standing
7194,Region_4,47,Wood,1452.7752775277527,37.37173717371737,74.74347434743474,7221.782178217822,Cloudy,3596.8596859685968,2029-09-11,71.93719371937195,7.193719371937194,775.4975497549756,359.68596859685965,"Concrete 80%, Wood 20%",Truss,Good,27.54975497549755,71.93719371937195,Standing
7252,Region_2,25,Steel,1464.086408640864,37.63276327632764,75.26552655265527,7279.207920792079,Sunny,3625.8625862586255,2029-11-08,72.51725172517251,7.251725172517252,780.1380138013801,362.58625862586257,"Steel 70%, Concrete 30%",Arch,Good,28.013801380138013,72.51725172517251,Standing
7310,Region_5,44,Concrete,1475.3975397539755,37.893789378937896,75.78757875787579,7336.633663366337,Windy,3654.8654865486546,2030-01-05,73.0973097309731,7.3097309730973095,784.7784778477848,365.4865486548655,"Concrete 80%, Wood 20%",Beam,Good,28.477847784778476,73.0973097309731,Standing
7368,Region_3,41,Wood,1486.7086708670868,38.154815481548155,76.30963096309631,7394.059405940594,Snowy,3683.8683868386834,2030-03-04,73.67736773677368,7.367736773677367,789.4189418941894,368.38683868386835,"Concrete 80%, Wood 20%",Truss,Good,28.94189418941894,73.67736773677368,Standing
7426,Region_1,39,Steel,1498.019801980198,38.415841584158414,76.83168316831683,7451.485148514851,Rainy,3712.8712871287125,2030-05-01,74.25742574257426,7.425742574257426,794.059405940594,371.28712871287127,"Steel 70%, Concrete 30%",Arch,Good,29.40594059405941,74.25742574257426,Standing
7484,Region_4,2,Concrete,1509.3309330933093,38.67686768676868,77.35373537353736,7508.910891089109,Cloudy,3741.8741874187417,2030-06-28,74.83748374837484,7.483748374837484,798.6998699869987,374.1874187418742,"Concrete 80%, Wood 20%",Beam,Good,29.869986998699872,74.83748374837484,Standing
7542,Region_2,44,Wood,1520.6420642064206,38.93789378937894,77.87578757875788,7566.336633663366,Sunny,3770.8770877087704,2030-08-25,75.41754175417542,7.541754175417542,803.3403340334033,377.08770877087704,"Concrete 80%, Wood 20%",Truss,Good,30.334033403340335,75.41754175417542,Standing
7600,Region_5,39,Steel,1531.953195319532,39.1989198919892,78.3978397839784,7623.762376237623,Windy,3799.8799879987996,2030-10-22,75.997599759976,7.5997599759976,807.980798079808,379.98799879987996,"Steel 70%, Concrete 30%",Arch,Good,30.7980798079808,75.997599759976,Standing
7658,Region_3,1,Concrete,1543.2643264326432,39.45994599459946,78.91989198919892,7681.188118811881,Snowy,3828.882888288829,2030-12-19,76.57765776577658,7.657765776577658,812.6212621262126,382.8882888288829,"Concrete 80%, Wood 20%",Beam,Good,31.26212621262126,76.57765776577658,Standing
7716,Region_1,43,Wood,1554.5754575457545,39.720972097209724,79.44194419441945,7738.6138613861385,Rainy,3857.8857885788575,2031-02-15,77.15771577157716,7.7157715771577156,817.2617261726173,385.7885788578858,"Concrete 80%, Wood 20%",Truss,Good,31.726172617261724,77.15771577157716,Standing
7774,Region_4,11,Steel,1565.8865886588658,39.981998199819984,79.96399639963997,7796.039603960396,Cloudy,3886.8886888688867,2031-04-14,77.73777377737774,7.773777377737773,821.9021902190219,388.68886888688866,"Steel 70%, Concrete 30%",Arch,Good,32.19021902190219,77.73777377737774,Standing
7832,Region_2,18,Concrete,1577.1977197719773,40.24302430243024,80.48604860486049,7853.465346534654,Sunny,3915.8915891589154,2031-06-11,78.31783178317832,7.831783178317832,826.5426542654266,391.5891589158916,"Concrete 80%, Wood 20%",Beam,Good,32.65426542654266,78.31783178317832,Standing
7890,Region_5,26,Wood,1588.5088508850886,40.5040504050405,81.008100810081,7910.891089108911,Windy,3944.8944894489446,2031-08-08,78.8978897889789,7.88978897889789,831.1831183118312,394.4894489448945,"Concrete 80%, Wood 20%",Truss,Good,33.11831183118312,78.8978897889789,Standing
7948,Region_3,33,Steel,1599.8199819981999,40.76507650765077,81.53015301530154,7968.316831683168,Snowy,3973.8973897389737,2031-10-05,79.47794779477948,7.947794779477948,835.8235823582359,397.38973897389735,"Steel 70%, Concrete 30%",Arch,Good,33.582358235823584,79.47794779477948,Standing
8006,Region_1,8,Concrete,1611.1311131113112,41.02610261026103,82.05220522052205,8025.742574257426,Rainy,4002.9002900290025,2031-12-02,80.05800580058006,8.005800580058006,840.4640464046405,400.29002900290027,"Concrete 80%, Wood 20%",Beam,Good,34.04640464046405,80.05800580058006,Collapsed
8064,Region_4,47,Wood,1622.4422442244224,41.28712871287129,82.57425742574257,8083.168316831683,Cloudy,4031.9031903190316,2032-01-29,80.63806380638064,8.063806380638065,845.1045104510451,403.1903190319032,"Concrete 80%, Wood 20%",Truss,Good,34.51045104510452,80.63806380638064,Collapsed
8122,Region_2,44,Steel,1633.7533753375337,41.54815481548155,83.0963096309631,8140.59405940594,Sunny,4060.9060906090604,2032-03-27,81.21812181218122,8.121812181218122,849.7449744974498,406.09060906090605,"Steel 70%, Concrete 30%",Arch,Good,34.97449744974497,81.21812181218122,Collapsed
8180,Region_5,2,Concrete,1645.064506450645,41.80918091809181,83.61836183618362,8198.019801980197,Windy,4089.9089908990895,2032-05-24,81.7981798179818,8.17981798179818,854.3854385438544,408.99089908990896,"Concrete 80%, Wood 20%",Beam,Good,35.43854385438544,81.7981798179818,Collapsed
8238,Region_3,14,Wood,1656.3756375637563,42.07020702070207,84.14041404140414,8255.445544554455,Snowy,4118.911891189118,2032-07-21,82.37823782378238,8.237823782378237,859.0259025902591,411.8911891189119,"Concrete 80%, Wood 20%",Truss,Good,35.9025902590259,82.37823782378238,Collapsed
8296,Region_1,36,Steel,1667.6867686768676,42.33123312331233,84.66246624662466,8312.871287128713,Rainy,4147.914791479147,2032-09-17,82.95829582958297,8.295829582958296,863.6663666366637,414.79147914791474,"Steel 70%, Concrete 30%",Arch,Good,36.36663666366637,82.95829582958297,Collapsed
8354,Region_4,1,Concrete,1678.9978997899789,42.5922592259226,85.1845184518452,8370.29702970297,Cloudy,4176.917691769177,2032-11-14,83.53835383538355,8.353835383538353,868.3068306830684,417.69176917691766,"Concrete 80%, Wood 20%",Beam,Good,36.830683068306826,83.53835383538355,Collapsed
8412,Region_2,9,Wood,1690.3090309030904,42.853285328532856,85.70657065706571,8427.722772277228,Sunny,4205.920592059206,2033-01-11,84.11841184118413,8.411841184118412,872.947294729473,420.5920592059206,"Concrete 80%, Wood 20%",Truss,Good,37.294729472947296,84.11841184118413,Collapsed
8470,Region_5,27,Steel,1701.6201620162017,43.114311431143115,86.22862286228623,8485.148514851486,Windy,4234.923492349235,2033-03-10,84.69846984698471,8.46984698469847,877.5877587758777,423.4923492349235,"Steel 70%, Concrete 30%",Arch,Good,37.758775877587766,84.69846984698471,Collapsed
8528,Region_3,35,Concrete,1712.931293129313,43.375337533753374,86.75067506750675,8542.574257425742,Snowy,4263.926392639263,2033-05-07,85.27852785278529,8.527852785278528,882.2282228222823,426.39263926392636,"Concrete 80%, Wood 20%",Beam,Good,38.22282228222822,85.27852785278529,Collapsed
8586,Region_1,47,Wood,1724.2424242424242,43.63636363636364,87.27272727272728,8600.0,Rainy,4292.929292929292,2033-07-04,85.85858585858587,8.585858585858587,886.868686868687,429.2929292929293,"Concrete 80%, Wood 20%",Truss,Good,38.68686868686869,85.85858585858587,Collapsed
8644,Region_4,15,Steel,1735.5535553555355,43.8973897389739,87.7947794779478,8657.425742574258,Cloudy,4321.932193219322,2033-08-31,86.43864386438645,8.643864386438644,891.5091509150916,432.1932193219322,"Steel 70%, Concrete 30%",Arch,Good,39.15091509150915,86.43864386438645,Collapsed
8702,Region_2,6,Concrete,1746.8646864686468,44.15841584158416,88.31683168316832,8714.851485148514,Sunny,4350.935093509351,2033-10-28,87.01870187018702,8.701870187018702,896.1496149614961,435.09350935093505,"Concrete 80%, Wood 20%",Beam,Good,39.61496149614962,87.01870187018702,Collapsed
8760,Region_5,32,Wood,1758.175817581758,44.41944194419442,88.83888388838884,8772.277227722772,Windy,4379.93799379938,2033-12-25,87.5987598759876,8.75987598759876,900.7900790079008,437.99379937993797,"Concrete 80%, Wood 20%",Truss,Good,40.079007900790074,87.5987598759876,Collapsed
8818,Region_3,5,Steel,1769.4869486948694,44.680468046804684,89.36093609360937,8829.70297029703,Snowy,4408.940894089408,2034-02-21,88.17881788178818,8.817881788178818,905.4305430543054,440.8940894089409,"Steel 70%, Concrete 30%",Arch,Good,40.543054305430545,88.17881788178818,Collapsed
8876,Region_1,3,Concrete,1780.7980798079807,44.94149414941494,89.88298829882989,8887.128712871287,Rainy,4437.943794379437,2034-04-20,88.75887588758876,8.875887588758875,910.0710071007101,443.79437943794375,"Concrete 80%, Wood 20%",Beam,Good,41.007100710071,88.75887588758876,Collapsed
8934,Region_4,24,Wood,1792.1092109210922,45.2025202520252,90.4050405040504,8944.554455445545,Cloudy,4466.9466946694665,2034-06-17,89.33893389338934,8.933893389338934,914.7114711471147,446.69466946694666,"Concrete 80%, Wood 20%",Truss,Good,41.47114711471147,89.33893389338934,Collapsed
8992,Region_2,9,Steel,1803.4203420342035,45.46354635463546,90.92709270927092,9001.980198019803,Sunny,4495.949594959496,2034-08-14,89.91899189918992,8.991899189918993,919.3519351935194,449.5949594959496,"Steel 70%, Concrete 30%",Arch,Good,41.93519351935194,89.91899189918992,Collapsed
9050,Region_5,5,Concrete,1814.7314731473148,45.72457245724573,91.44914491449146,9059.405940594059,Windy,4524.952495249525,2034-10-11,90.4990499049905,9.04990499049905,923.992399239924,452.4952495249525,"Concrete 80%, Wood 20%",Beam,Good,42.3992399239924,90.4990499049905,Collapsed
9108,Region_3,4,Wood,1826.042604260426,45.98559855985599,91.97119711971197,9116.831683168317,Snowy,4553.955395539553,2034-12-08,91.07910791079108,9.107910791079108,928.6328632863286,455.39553955395536,"Concrete 80%, Wood 20%",Truss,Good,42.86328632863287,91.07910791079108,Collapsed
9166,Region_1,26,Steel,1837.3537353735373,46.246624662466246,92.49324932493249,9174.257425742575,Rainy,4582.958295829582,2035-02-04,91.65916591659166,9.165916591659165,933.2733273327333,458.2958295829583,"Steel 70%, Concrete 30%",Arch,Good,43.32733273327332,91.65916591659166,Collapsed
9224,Region_4,41,Concrete,1848.6648664866486,46.50765076507651,93.01530153015302,9231.683168316831,Cloudy,4611.9611961196115,2035-04-03,92.23922392239224,9.223922392239224,937.9137913791379,461.1961196119612,"Concrete 80%, Wood 20%",Beam,Good,43.79137913791379,92.23922392239224,Collapsed
9282,Region_2,42,Wood,1859.97599759976,46.76867686768677,93.53735373537354,9289.10891089109,Sunny,4640.964096409641,2035-05-31,92.81928192819282,9.281928192819281,942.5542554255426,464.09640964096405,"Concrete 80%, Wood 20%",Truss,Good,44.25542554255425,92.81928192819282,Collapsed
9340,Region_5,42,Steel,1871.2871287128712,47.02970297029703,94.05940594059406,9346.534653465347,Windy,4669.96699669967,2035-07-28,93.3993399339934,9.33993399339934,947.1947194719472,466.996699669967,"Steel 70%, Concrete 30%",Arch,Good,44.71947194719472,93.3993399339934,Collapsed
9398,Region_3,48,Concrete,1882.5982598259825,47.29072907290729,94.58145814581458,9403.960396039603,Snowy,4698.969896989699,2035-09-24,93.97939793979398,9.397939793979399,951.8351835183519,469.8969896989699,"Concrete 80%, Wood 20%",Beam,Good,45.18351835183519,93.97939793979398,Collapsed
9456,Region_1,33,Wood,1893.9093909390938,47.551755175517556,95.10351035103511,9461.386138613861,Rainy,4727.972797279727,2035-11-21,94.55945594559456,9.455945594559456,956.4756475647565,472.79727972797275,"Concrete 80%, Wood 20%",Truss,Good,45.647564756475646,94.55945594559456,Collapsed
9514,Region_4,7,Steel,1905.2205220522053,47.812781278127815,95.62556255625563,9518.81188118812,Cloudy,4756.975697569756,2036-01-18,95.13951395139514,9.513951395139514,961.1161116111612,475.69756975697567,"Steel 70%, Concrete 30%",Arch,Good,46.111611161116116,95.13951395139514,Collapsed
9572,Region_2,8,Concrete,1916.5316531653166,48.073807380738074,96.14761476147615,9576.237623762376,Sunny,4785.978597859786,2036-03-16,95.71957195719573,9.571957195719571,965.7565756575658,478.5978597859786,"Concrete 80%, Wood 20%",Beam,Good,46.57565756575657,95.71957195719573,Collapsed
9630,Region_5,48,Wood,1927.8427842784279,48.33483348334833,96.66966696669667,9633.663366336634,Windy,4814.981498149815,2036-05-13,96.2996299629963,9.62996299629963,970.3970397039704,481.49814981498145,"Concrete 80%, Wood 20%",Truss,Good,47.03970397039704,96.2996299629963,Collapsed
9688,Region_3,7,Steel,1939.1539153915392,48.5958595859586,97.1917191719172,9691.089108910892,Snowy,4843.984398439844,2036-07-10,96.87968796879689,9.687968796879687,975.0375037503751,484.39843984398436,"Steel 70%, Concrete 30%",Arch,Good,47.5037503750375,96.87968796879689,Collapsed
9746,Region_1,32,Concrete,1950.4650465046504,48.85688568856886,97.71377137713772,9748.514851485148,Rainy,4872.987298729872,2036-09-06,97.45974597459747,9.745974597459746,979.6779677967797,487.2987298729873,"Concrete 80%, Wood 20%",Beam,Good,47.96779677967797,97.45974597459747,Collapsed
9804,Region_4,29,Wood,1961.7761776177617,49.11791179117912,98.23582358235824,9805.940594059406,Cloudy,4901.990199019901,2036-11-03,98.03980398039805,9.803980398039805,984.3184318431844,490.1990199019902,"Concrete 80%, Wood 20%",Truss,Good,48.43184318431844,98.03980398039805,Collapsed
9862,Region_2,35,Steel,1973.087308730873,49.37893789378938,98.75787578757875,9863.366336633664,Sunny,4930.993099309931,2036-12-31,98.61986198619863,9.861986198619862,988.958895889589,493.09930993099306,"Steel 70%, Concrete 30%",Arch,Good,48.895889588958894,98.61986198619863,Collapsed
9920,Region_5,45,Concrete,1984.3984398439843,49.63996399639964,99.27992799279929,9920.79207920792,Windy,4959.99599959996,2037-02-27,99.19991999199921,9.91999199919992,993.5993599359937,495.999599959996,"Concrete 80%, Wood 20%",Beam,Good,49.359935993599365,99.19991999199921,Collapsed
9978,Region_3,12,Wood,1995.7095709570956,49.9009900990099,99.8019801980198,9978.217821782178,Snowy,4988.998899889989,2037-04-26,99.77997799779979,9.977997799779978,998.2398239823983,498.8998899889989,"Concrete 80%, Wood 20%",Truss,Good,49.82398239823982,99.77997799779979,Collapsed
9999,Region_4,5,Wood,1999.8049804980499,49.995499549955,99.99099909991,9999.009900990099,Cloudy,4999.499949994999,2037-05-17,99.9899989999,9.998999899989998,999.9199919992,499.94999499949995,"Concrete 80%, Wood 20%",Truss,Good,49.99199919991999,99.9899989999,Collapsed
10000,Region_5,7,Steel,2000.0,50.0,100.0,10000.0,Windy,5000.0,2037-05-18,100.0,10.0,1000.0,500.0,"Steel 70%, Concrete 30%",Arch,Good,50.0,100.0,Collapsed